Workbook

Sheet Overview
A1: Foundation of Goodness — Food & Education Distributions (Dec 2025 – Feb 2026)
A3: Metric | B3: Value | C3: Note
A4: FOOD — dry-ration packs
A5: Packs distributed (official total) | B5: 12578 | C5: Target was 10,000 — exceeded
A6: Sum of weekly totals | B6: ='Food - Weekly'!B8 -> 12577 | C6: Weekly table adds to 12,577 (1 less than the stated total)
A7: Villages covered | B7: 330
A8: Sum of area-level entries (as listed) | B8: ='Food - All Deliveries'!D109 -> 16713 | C8: Higher than 12,578 — the report lists some deliveries twice (weekly table + photo caption). Treat area totals as upper bounds.
A9: EDUCATION — Essential School Supply Packs (ESSP)
A10: ESSP requests (island-wide) | B10: 7475
A11: ESSP packs received | B11: 4075
A12: ESSP packs distributed (as of 3 Feb 2026) | B12: 3720
A13: ESSP packs pending hand-out | B13: =B11-B12 -> 355 | C13: Received − distributed
A14: Requests still unmet | B14: =B10-B12 -> 3755 | C14: Requests − distributed
A15: Students listed by school | B15: ='Education - Schools'!D31 -> 3569 | C15: Schools named in the report; the rest of the 3,720 were not itemised
A16: Cost per ESSP pack (Rs.) | B16: 5400 | C16: USD 18 per pack; no admin cost deducted
A17: Value of packs distributed (Rs.) | B17: =B12*B16 -> 20088000

Sheet Food - Weekly
A1: Period | B1: Packs
A2: Week 1 (1st week of Dec 2025) | B2: 1136
A3: Week 2 (2nd week of Dec 2025) | B3: 2986
A4: Week 3 (3rd week of Dec 2025) | B4: 3811
A5: Week 4 | B5: 2468
A6: Week 5 | B6: 1210
A7: Week 6 (pending distribution) | B7: 966
A8: TOTAL | B8: =SUM(B2:B7) -> 12577
A10: Report states 12,578 in total.

Sheet Food - All Deliveries
A1: Area | B1: Province (as in report) | C1: District | D1: Packs | E1: When | F1: Note
A2: Badulla 2 | B2: Uva | C2: Badulla | D2: 600 | E2: 13 Dec 2025
A3: Badulla 1 – Hali-Ela DS Division | B3: Uva | C3: Badulla | D3: 399 | E3: 9 Dec 2025
A4: Mihindumpitiya / Lunugala – 1 | B4: Uva | C4: Badulla | D4: 420 | E4: Wk 5&6
A5: Kandaketiya | B5: Uva | C5: Badulla | D5: 352 | E5: 18 Dec 2025
A6: Jaffna | B6: Northern | C6: Jaffna | D6: 310 | E6: 11–12 Dec 2025
A7: Nuwara Eliya (Kothmale & N.Eliya) | B7: Central | C7: Nuwara Eliya | D7: 356 | E7: Multiple | F7: Kothmale 250 may repeat the separate 'Kothmale' row
A8: Nuwara Eliya (Kothmale & N.Eliya) | B8: Central | C8: Nuwara Eliya | D8: 250 | E8: Multiple | F8: Kothmale 250 may repeat the separate 'Kothmale' row
A9: Passara | B9: Uva | C9: Badulla | D9: 436 | E9: Wk 5&6
A10: Mihindumpitiya / Lunugala – 2 | B10: Uva | C10: Badulla | D10: 240 | E10: Wk 5&6
A11: Chavakachcheri | B11: Northern | C11: Jaffna | D11: 300 | E11: Wk 5&6
A12: Palavi, Wanathawilluwa & Madurankuliya | B12: North Western | C12: Puttalam | D12: 250 | E12: 10 Dec 2025
A13: Mannar | B13: Northern | C13: Mannar | D13: 250 | E13: 10 & 18 Dec 2025
A14: Mannar | B14: Northern | C14: Mannar | D14: 200 | E14: Wk 5&6
A15: Pallai | B15: Northern | C15: Kilinochchi | D15: 200 | E15: Wk 1–3
A16: Pallai | B16: Northern | C16: Kilinochchi | D16: 235 | E16: Wk 1–3
A17: Pallai | B17: Northern | C17: Kilinochchi | D17: 200 | E17: Wk 1–3
A18: Pallai | B18: Northern | C18: Kilinochchi | D18: 200 | E18: Wk 1–3
A19: Oddusuddan | B19: Northern | C19: Mullaitivu | D19: 150 | E19: Wk 1
A20: Oddusuddan | B20: Northern | C20: Mullaitivu | D20: 235 | E20: Wk 3
A21: Thirukkovil | B21: Eastern | C21: Ampara | D21: 200 | E21: Wk 3 | F21: Wk3 + dated entry may be the same delivery
A22: Thirukkovil | B22: Eastern | C22: Ampara | D22: 200 | E22: 19 Dec 2025 | F22: Wk3 + dated entry may be the same delivery
A23: Hatton (incl. Hatton/N.Eliya) | B23: Central | C23: Nuwara Eliya | D23: 150 | E23: 12–13 Dec 2025
A24: Hatton (incl. Hatton/N.Eliya) | B24: Central | C24: Nuwara Eliya | D24: 169 | E24: 24 Dec 2025
A25: Dambulla (incl. Laggala) | B25: Central | C25: Matale | D25: 150 | E25: Multiple
A26: Dambulla (incl. Laggala) | B26: Central | C26: Matale | D26: 50 | E26: Multiple
A27: Dambulla (incl. Laggala) | B27: Central | C27: Matale | D27: 150 | E27: Multiple
A28: Bandarawela | B28: Uva | C28: Badulla | D28: 103 | E28: Wk 1
A29: Bandarawela | B29: Uva | C29: Badulla | D29: 100 | E29: Wk 3
A30: Bandarawela | B30: Uva | C30: Badulla | D30: 100 | E30: 19 Dec 2025
A31: Nawalapitiya | B31: Central | C31: Kandy | D31: 150 | E31: 18 Dec 2025
A32: Nawalapitiya | B32: Central | C32: Kandy | D32: 100 | E32: Wk 3
A33: Nuwara Eliya & Welimada | B33: Central/Uva | C33: Nuwara Eliya / Badulla | D33: 85 | E33: 13 Dec 2025 | F33: Spans two districts
A34: Nuwara Eliya & Welimada | B34: Central/Uva | C34: Nuwara Eliya / Badulla | D34: 234 | E34: 23 Dec 2025 | F34: Spans two districts
A35: Angoda | B35: Western | C35: Colombo | D35: 125 | E35: 13 Dec 2025
A36: Ja-Ela / Makawita | B36: Western | C36: Gampaha | D36: 125 | E36: 12 Dec 2025 | F36: Also 1,000 water
A37: Ja-Ela / Makawita | B37: Western | C37: Gampaha | D37: 125 | E37: Wk 2 | F37: Also 1,000 water
A38: Ja-Ela / Makawita | B38: Western | C38: Gampaha | D38: 130 | E38: 23 Dec 2025 | F38: Also 1,000 water
A39: Halmulla, Wellampitiya | B39: Western | C39: Colombo | D39: 125 | E39: 13 Dec 2025 | F39: Wk + dated entry may be the same delivery
A40: Halmulla, Wellampitiya | B40: Western | C40: Colombo | D40: 125 | E40: Wk 2 | F40: Wk + dated entry may be the same delivery
...

Sheet Food - By Area
A1: Rank | B1: Area | C1: District | D1: Total packs | E1: No. of deliveries | F1: Need signal
A2: 1 | B2: Soranathota / Haliella / Badulla DS Division | C2: Badulla | D2: =SUMIF('Food - All Deliveries'!$A$2:$A$108,B2,'Food - All Deliveries'!$D$2:$D$108) -> 939 | E2: =COUNTIF('Food - All Deliveries'!$A$2:$A$108,B2) -> 3 | F2: Acute (300+ in one delivery)
A3: 2 | B3: Pallai | C3: Kilinochchi | D3: =SUMIF('Food - All Deliveries'!$A$2:$A$108,B3,'Food - All Deliveries'!$D$2:$D$108) -> 835 | E3: =COUNTIF('Food - All Deliveries'!$A$2:$A$108,B3) -> 4 | F3: Recurring (2+ deliveries)
A4: 3 | B4: Nuwara Eliya (Kothmale & N.Eliya) | C4: Nuwara Eliya | D4: =SUMIF('Food - All Deliveries'!$A$2:$A$108,B4,'Food - All Deliveries'!$D$2:$D$108) -> 606 | E4: =COUNTIF('Food - All Deliveries'!$A$2:$A$108,B4) -> 2 | F4: Acute (300+ in one delivery)
A5: 4 | B5: Badulla 2 | C5: Badulla | D5: =SUMIF('Food - All Deliveries'!$A$2:$A$108,B5,'Food - All Deliveries'!$D$2:$D$108) -> 600 | E5: =COUNTIF('Food - All Deliveries'!$A$2:$A$108,B5) -> 1 | F5: Acute (300+ in one delivery)
A6: 5 | B6: Mannar | C6: Mannar | D6: =SUMIF('Food - All Deliveries'!$A$2:$A$108,B6,'Food - All Deliveries'!$D$2:$D$108) -> 450 | E6: =COUNTIF('Food - All Deliveries'!$A$2:$A$108,B6) -> 2 | F6: Recurring (2+ deliveries)
A7: 6 | B7: Passara | C7: Badulla | D7: =SUMIF('Food - All Deliveries'!$A$2:$A$108,B7,'Food - All Deliveries'!$D$2:$D$108) -> 436 | E7: =COUNTIF('Food - All Deliveries'!$A$2:$A$108,B7) -> 1 | F7: Acute (300+ in one delivery)
A8: 7 | B8: Mihindumpitiya / Lunugala – 1 | C8: Badulla | D8: =SUMIF('Food - All Deliveries'!$A$2:$A$108,B8,'Food - All Deliveries'!$D$2:$D$108) -> 420 | E8: =COUNTIF('Food - All Deliveries'!$A$2:$A$108,B8) -> 1 | F8: Acute (300+ in one delivery)
A9: 8 | B9: Thirukkovil | C9: Ampara | D9: =SUMIF('Food - All Deliveries'!$A$2:$A$108,B9,'Food - All Deliveries'!$D$2:$D$108) -> 400 | E9: =COUNTIF('Food - All Deliveries'!$A$2:$A$108,B9) -> 2 | F9: Recurring (2+ deliveries)
A10: 9 | B10: Batticaloa | C10: Batticaloa | D10: =SUMIF('Food - All Deliveries'!$A$2:$A$108,B10,'Food - All Deliveries'!$D$2:$D$108) -> 400 | E10: =COUNTIF('Food - All Deliveries'!$A$2:$A$108,B10) -> 2 | F10: Acute (300+ in one delivery)
A11: 10 | B11: Badulla 1 – Hali-Ela DS Division | C11: Badulla | D11: =SUMIF('Food - All Deliveries'!$A$2:$A$108,B11,'Food - All Deliveries'!$D$2:$D$108) -> 399 | E11: =COUNTIF('Food - All Deliveries'!$A$2:$A$108,B11) -> 1 | F11: Acute (300+ in one delivery)
A12: 11 | B12: Oddusuddan | C12: Mullaitivu | D12: =SUMIF('Food - All Deliveries'!$A$2:$A$108,B12,'Food - All Deliveries'!$D$2:$D$108) -> 385 | E12: =COUNTIF('Food - All Deliveries'!$A$2:$A$108,B12) -> 2 | F12: Recurring (2+ deliveries)
A13: 12 | B13: Ja-Ela / Makawita | C13: Gampaha | D13: =SUMIF('Food - All Deliveries'!$A$2:$A$108,B13,'Food - All Deliveries'!$D$2:$D$108) -> 380 | E13: =COUNTIF('Food - All Deliveries'!$A$2:$A$108,B13) -> 3 | F13: Recurring (2+ deliveries)
... A29: 28 | B29: Gampola | C29: Kandy | D29: =SUMIF('Food - All Deliveries'!$A$2:$A$108,B29,'Food - All Deliveries'!$D$2:$D$108) -> 272 | E29: =COUNTIF('Food - All Deliveries'!$A$2:$A$108,B29) -> 2 | F29: Recurring (2+ deliveries)
A30: 29 | B30: Palavi, Wanathawilluwa & Madurankuliya | C30: Puttalam | D30: =SUMIF('Food - All Deliveries'!$A$2:$A$108,B30,'Food - All Deliveries'!$D$2:$D$108) -> 250 | E30: =COUNTIF('Food - All Deliveries'!$A$2:$A$108,B30) -> 1
A31: 30 | B31: Nawalapitiya | C31: Kandy | D31: =SUMIF('Food - All Deliveries'!$A$2:$A$108,B31,'Food - All Deliveries'!$D$2:$D$108) -> 250 | E31: =COUNTIF('Food - All Deliveries'!$A$2:$A$108,B31) -> 2 | F31: Recurring (2+ deliveries)
A32: 31 | B32: Halmulla, Wellampitiya | C32: Colombo | D32: =SUMIF('Food - All Deliveries'!$A$2:$A$108,B32,'Food - All Deliveries'!$D$2:$D$108) -> 250 | E32: =COUNTIF('Food - All Deliveries'!$A$2:$A$108,B32) -> 2 | F32: Recurring (2+ deliveries)
A33: 32 | B33: Hasalaka (incl. Udaththawa) | C33: Kandy | D33: =SUMIF('Food - All Deliveries'!$A$2:$A$108,B33,'Food - All Deliveries'!$D$2:$D$108) -> 250 | E33: =COUNTIF('Food - All Deliveries'!$A$2:$A$108,B33) -> 2 | F33: Recurring (2+ deliveries)
A34: 33 | B34: Kothmale | C34: Nuwara Eliya | D34: =SUMIF('Food - All Deliveries'!$A$2:$A$108,B34,'Food - All Deliveries'!$D$2:$D$108) -> 250 | E34: =COUNTIF('Food - All Deliveries'!$A$2:$A$108,B34) -> 1
A35: 34 | B35: Mihindumpitiya / Lunugala – 2 | C35: Badulla | D35: =SUMIF('Food - All Deliveries'!$A$2:$A$108,B35,'Food - All Deliveries'!$D$2:$D$108) -> 240 | E35: =COUNTIF('Food - All Deliveries'!$A$2:$A$108,B35) -> 1
A36: 35 | B36: Rikillagaskada – Hanguranketa | C36: Nuwara Eliya | D36: =SUMIF('Food - All Deliveries'!$A$2:$A$108,B36,'Food - All Deliveries'!$D$2:$D$108) -> 237 | E36: =COUNTIF('Food - All Deliveries'!$A$2:$A$108,B36) -> 3 | F36: Recurring (2+ deliveries)
A37: 36 | B37: Ankumbura, Karagahapitiya – Kandy | C37: Kandy | D37: =SUMIF('Food - All Deliveries'!$A$2:$A$108,B37,'Food - All Deliveries'!$D$2:$D$108) -> 228 | E37: =COUNTIF('Food - All Deliveries'!$A$2:$A$108,B37) -> 2 | F37: Recurring (2+ deliveries)
A38: 37 | B38: Kottikawatta | C38: Colombo | D38: =SUMIF('Food - All Deliveries'!$A$2:$A$108,B38,'Food - All Deliveries'!$D$2:$D$108) -> 200 | E38: =COUNTIF('Food - All Deliveries'!$A$2:$A$108,B38) -> 2 | F38: Recurring (2+ deliveries)
A39: 38 | B39: Pemaduwa – Anuradhapura | C39: Anuradhapura | D39: =SUMIF('Food - All Deliveries'!$A$2:$A$108,B39,'Food - All Deliveries'!$D$2:$D$108) -> 200 | E39: =COUNTIF('Food - All Deliveries'!$A$2:$A$108,B39) -> 2 | F39: Recurring (2+ deliveries)
A40: 39 | B40: Sittandy | C40: Batticaloa | D40: =SUMIF('Food - All Deliveries'!$A$2:$A$108,B40,'Food - All Deliveries'!$D$2:$D$108) -> 200 | E40: =COUNTIF('Food - All Deliveries'!$A$2:$A$108,B40) -> 2 | F40: Recurring (2+ deliveries)
A41: 40 | B41: Ridigama | C41: Kurunegala | D41: =SUMIF('Food - All Deliveries'!$A$2:$A$108,B41,'Food - All Deliveries'!$D$2:$D$108) -> 200 | E41: =COUNTIF('Food - All Deliveries'!$A$2:$A$108,B41) -> 2 | F41: Recurring (2+ deliveries)
A42: 41 | B42: Kankuveli | C42: Trincomalee | D42: =SUMIF('Food - All Deliveries'!$A$2:$A$108,B42,'Food - All Deliveries'!$D$2:$D$108) -> 200 | E42: =COUNTIF('Food - All Deliveries'!$A$2:$A$108,B42) -> 1
A43: 42 | B43: Giriulla – Kurunegala | C43: Kurunegala | D43: =SUMIF('Food - All Deliveries'!$A$2:$A$108,B43,'Food - All Deliveries'!$D$2:$D$108) -> 190 | E43: =COUNTIF('Food - All Deliveries'!$A$2:$A$108,B43) -> 2 | F43: Recurring (2+ deliveries)
A44: 43 | B44: Kandy – Pahathahewahata | C44: Kandy | D44: =SUMIF('Food - All Deliveries'!$A$2:$A$108,B44,'Food - All Deliveries'!$D$2:$D$108) -> 170 | E44: =COUNTIF('Food - All Deliveries'!$A$2:$A$108,B44) -> 1
A45: 44 | B45: Ratnapura | C45: Ratnapura | D45: =SUMIF('Food - All Deliveries'!$A$2:$A$108,B45,'Food - All Deliveries'!$D$2:$D$108) -> 150 | E45: =COUNTIF('Food - All Deliveries'!$A$2:$A$108,B45) -> 1
A46: 45 | B46: Cheddikulam | C46: Vavuniya | D46: =SUMIF('Food - All Deliveries'!$A$2:$A$108,B46,'Food - All Deliveries'!$D$2:$D$108) -> 150 | E46: =COUNTIF('Food - All Deliveries'!$A$2:$A$108,B46) -> 1
A47: 46 | B47: Mathagal | C47: Jaffna | D47: =SUMIF('Food - All Deliveries'!$A$2:$A$108,B47,'Food - All Deliveries'!$D$2:$D$108) -> 150 | E47: =COUNTIF('Food - All Deliveries'!$A$2:$A$108,B47) -> 1
A48: 47 | B48: Galaha | C48: Kandy | D48: =SUMIF('Food - All Deliveries'!$A$2:$A$108,B48,'Food - All Deliveries'!$D$2:$D$108) -> 150 | E48: =COUNTIF('Food - All Deliveries'!$A$2:$A$108,B48) -> 1
A49: 48 | B49: Ududumbara, Hunnasgiriya, Kandy | C49: Kandy | D49: =SUMIF('Food - All Deliveries'!$A$2:$A$108,B49,'Food - All Deliveries'!$D$2:$D$108) -> 150 | E49: =COUNTIF('Food - All Deliveries'!$A$2:$A$108,B49) -> 1
A50: 49 | B50: Nagahawela – Kotikawatta | C50: Colombo | D50: =SUMIF('Food - All Deliveries'!$A$2:$A$108,B50,'Food - All Deliveries'!$D$2:$D$108) -> 130 | E50: =COUNTIF('Food - All Deliveries'!$A$2:$A$108,B50) -> 1
A51: 50 | B51: Dehiattakandiya | C51: Ampara | D51: =SUMIF('Food - All Deliveries'!$A$2:$A$108,B51,'Food - All Deliveries'!$D$2:$D$108) -> 128 | E51: =COUNTIF('Food - All Deliveries'!$A$2:$A$108,B51) -> 1
A52: 51 | B52: Maskeliya | C52: Nuwara Eliya | D52: =SUMIF('Food - All Deliveries'!$A$2:$A$108,B52,'Food - All Deliveries'!$D$2:$D$108) -> 126 | E52: =COUNTIF('Food - All Deliveries'!$A$2:$A$108,B52) -> 2 | F52: Recurring (2+ deliveries)
A53: 52 | B53: Moragolla Village, Badulla | C53: Badulla | D53: =SUMIF('Food - All Deliveries'!$A$2:$A$108,B53,'Food - All Deliveries'!$D$2:$D$108) -> 126 | E53: =COUNTIF('Food - All Deliveries'!$A$2:$A$108,B53) -> 1
A54: 53 | B54: Angoda | C54: Colombo | D54: =SUMIF('Food - All Deliveries'!$A$2:$A$108,B54,'Food - All Deliveries'!$D$2:$D$108) -> 125 | E54: =COUNTIF('Food - All Deliveries'!$A$2:$A$108,B54) -> 1
A55: 54 | B55: Onagama – Polonnaruwa | C55: Polonnaruwa | D55: =SUMIF('Food - All Deliveries'!$A$2:$A$108,B55,'Food - All Deliveries'!$D$2:$D$108) -> 120 | E55: =COUNTIF('Food - All Deliveries'!$A$2:$A$108,B55) -> 1
...

Sheet Education - How ESSP Works
A1: How Foundation of Goodness gives education support
A2: Each child receives one Essential School Supply Pack (ESSP), requested through their school or as an individual request from a struggling student.
A4: Item in each pack | B4: Qty per child | C4: Purpose
A5: School bag | B5: 1 | C5: Carry books to school
A6: Exercise books | B6: 8 | C6: Writing books for the school term
A7: Pens | B7: 2 | C7: Writing
A8: Shoe voucher | B8: 1 | C8: Redeemed for a pair of school shoes
A10: Cost per pack (Rs.) | B10: 5400
A11: Cost per pack (USD) | B11: 18
A12: Admin cost deducted | B12: None
A14: Delivery channel | C14: Mostly school-by-school distributions (whole class/school), plus individual requests from struggling students (e.g. Seenigama, Kolonnawa, island-wide).

Sheet Education - Schools
A1: Rank | B1: School / Centre | C1: District | D1: Students (packs) | E1: School bags | F1: Exercise books | G1: Pens | H1: Shoe vouchers | I1: Pack value (Rs.)
A2: 1 | B2: Mawadavila Maliyadewam Maha Vidyalaya | C2: Galle | D2: 375 | E2: =D2*'Education - How ESSP Works'!$B$5 -> 375 | F2: =D2*'Education - How ESSP Works'!$B$6 -> 3000 | G2: =D2*'Education - How ESSP Works'!$B$7 -> 750 | H2: =D2*'Education - How ESSP Works'!$B$8 -> 375 | I2: =D2*'Education - How ESSP Works'!$B$10 -> 2025000
A3: 2 | B3: Minhaj Maha Vidyalaya – Nikagolla | C3: Matale | D3: 348 | E3: =D3*'Education - How ESSP Works'!$B$5 -> 348 | F3: =D3*'Education - How ESSP Works'!$B$6 -> 2784 | G3: =D3*'Education - How ESSP Works'!$B$7 -> 696 | H3: =D3*'Education - How ESSP Works'!$B$8 -> 348 | I3: =D3*'Education - How ESSP Works'!$B$10 -> 1879200
A4: 3 | B4: Thambalawewa Primary School | C4: Polonnaruwa | D4: 282 | E4: =D4*'Education - How ESSP Works'!$B$5 -> 282 | F4: =D4*'Education - How ESSP Works'!$B$6 -> 2256 | G4: =D4*'Education - How ESSP Works'!$B$7 -> 564 | H4: =D4*'Education - How ESSP Works'!$B$8 -> 282 | I4: =D4*'Education - How ESSP Works'!$B$10 -> 1522800
A5: 4 | B5: Bt/Vinayagar Kiramam Alaimagal Vidyalayam | C5: Batticaloa | D5: 270 | E5: =D5*'Education - How ESSP Works'!$B$5 -> 270 | F5: =D5*'Education - How ESSP Works'!$B$6 -> 2160 | G5: =D5*'Education - How ESSP Works'!$B$7 -> 540 | H5: =D5*'Education - How ESSP Works'!$B$8 -> 270 | I5: =D5*'Education - How ESSP Works'!$B$10 -> 1458000
A6: 5 | B6: Kn/Mukkompan Maha Vidyalayam – Pallai | C6: Kilinochchi | D6: 260 | E6: =D6*'Education - How ESSP Works'!$B$5 -> 260 | F6: =D6*'Education - How ESSP Works'!$B$6 -> 2080 | G6: =D6*'Education - How ESSP Works'!$B$7 -> 520 | H6: =D6*'Education - How ESSP Works'!$B$8 -> 260 | I6: =D6*'Education - How ESSP Works'!$B$10 -> 1404000
A7: 6 | B7: J/Columbuthurai Hindu Maha Vidyalayam | C7: Jaffna | D7: 252 | E7: =D7*'Education - How ESSP Works'!$B$5 -> 252 | F7: =D7*'Education - How ESSP Works'!$B$6 -> 2016 | G7: =D7*'Education - How ESSP Works'!$B$7 -> 504 | H7: =D7*'Education - How ESSP Works'!$B$8 -> 252 | I7: =D7*'Education - How ESSP Works'!$B$10 -> 1360800
A8: 7 | B8: Tk/Mandanai Tamil Mixed School | C8: Ampara | D8: 247 | E8: =D8*'Education - How ESSP Works'!$B$5 -> 247 | F8: =D8*'Education - How ESSP Works'!$B$6 -> 1976 | G8: =D8*'Education - How ESSP Works'!$B$7 -> 494 | H8: =D8*'Education - How ESSP Works'!$B$8 -> 247 | I8: =D8*'Education - How ESSP Works'!$B$10 -> 1333800
A9: 8 | B9: Sudharmarama Dhamma School | C9: Ratnapura | D9: 192 | E9: =D9*'Education - How ESSP Works'!$B$5 -> 192 | F9: =D9*'Education - How ESSP Works'!$B$6 -> 1536 | G9: =D9*'Education - How ESSP Works'!$B$7 -> 384 | H9: =D9*'Education - How ESSP Works'!$B$8 -> 192 | I9: =D9*'Education - How ESSP Works'!$B$10 -> 1036800
A10: 9 | B10: B/Kukulapola Kanishta Vidyalaya | C10: Badulla | D10: 167 | E10: =D10*'Education - How ESSP Works'!$B$5 -> 167 | F10: =D10*'Education - How ESSP Works'!$B$6 -> 1336 | G10: =D10*'Education - How ESSP Works'!$B$7 -> 334 | H10: =D10*'Education - How ESSP Works'!$B$8 -> 167 | I10: =D10*'Education - How ESSP Works'!$B$10 -> 901800
A11: 10 | B11: Uppalawatta Junior School | C11: Puttalam | D11: 150 | E11: =D11*'Education - How ESSP Works'!$B$5 -> 150 | F11: =D11*'Education - How ESSP Works'!$B$6 -> 1200 | G11: =D11*'Education - How ESSP Works'!$B$7 -> 300 | H11: =D11*'Education - How ESSP Works'!$B$8 -> 150 | I11: =D11*'Education - How ESSP Works'!$B$10 -> 810000
A12: 11 | B12: Yatawatta Nandana Vidyalaya | C12: Matale | D12: 150 | E12: =D12*'Education - How ESSP Works'!$B$5 -> 150 | F12: =D12*'Education - How ESSP Works'!$B$6 -> 1200 | G12: =D12*'Education - How ESSP Works'!$B$7 -> 300 | H12: =D12*'Education - How ESSP Works'!$B$8 -> 150 | I12: =D12*'Education - How ESSP Works'!$B$10 -> 810000
A13: 12 | B13: Kincora Tamil Vidyalayam | C13: Nuwara Eliya | D13: 100 | E13: =D13*'Education - How ESSP Works'!$B$5 -> 100 | F13: =D13*'Education - How ESSP Works'!$B$6 -> 800 | G13: =D13*'Education - How ESSP Works'!$B$7 -> 200 | H13: =D13*'Education - How ESSP Works'!$B$8 -> 100 | I13: =D13*'Education - How ESSP Works'!$B$10 -> 540000
... A30: 29 | B30: Requests from struggling students – Kolonnawa | C30: Colombo | D30: 3 | E30: =D30*'Education - How ESSP Works'!$B$5 -> 3 | F30: =D30*'Education - How ESSP Works'!$B$6 -> 24 | G30: =D30*'Education - How ESSP Works'!$B$7 -> 6 | H30: =D30*'Education - How ESSP Works'!$B$8 -> 3 | I30: =D30*'Education - How ESSP Works'!$B$10 -> 16200
B31: TOTAL | D31: =SUM(D2:D30) -> 3569 | E31: =SUM(E2:E30) -> 3569 | F31: =SUM(F2:F30) -> 28552 | G31: =SUM(G2:G30) -> 7138 | H31: =SUM(H2:H30) -> 3569 | I31: =SUM(I2:I30) -> 19272600

Sheet By District - Coverage vs Need
A1: District | B1: Food packs (as listed) | C1: Food deliveries | D1: Food insecure households 2024 (WFP %) | E1: Food: gap flag | F1: ESSP students | G1: Schools / centres | H1: Education priority rank (1 = most need) | I1: Education: gap flag
A2: Ampara | B2: =SUMIF('Food - All Deliveries'!$C$2:$C$108,A2,'Food - All Deliveries'!$D$2:$D$108) -> 578 | C2: =COUNTIF('Food - All Deliveries'!$C$2:$C$108,A2) -> 4 | D2: 18.4 | E2: =IF(AND(D2>=20,B2<500),"High need, low coverage",IF(B2=0,"No food packs yet","")) | F2: =SUMIF('Education - Schools'!$C$2:$C$30,A2,'Education - Schools'!$D$2:$D$30) -> 247 | G2: =COUNTIF('Education - Schools'!$C$2:$C$30,A2) -> 1 | H2: 20 | I2: =IF(AND(H2<=10,F2<150),"High need, low coverage",IF(F2=0,"No ESSP yet",""))
A3: Anuradhapura | B3: =SUMIF('Food - All Deliveries'!$C$2:$C$108,A3,'Food - All Deliveries'!$D$2:$D$108) -> 200 | C3: =COUNTIF('Food - All Deliveries'!$C$2:$C$108,A3) -> 2 | D3: 12.8 | E3: =IF(AND(D3>=20,B3<500),"High need, low coverage",IF(B3=0,"No food packs yet","")) | F3: =SUMIF('Education - Schools'!$C$2:$C$30,A3,'Education - Schools'!$D$2:$D$30) -> 0 | G3: =COUNTIF('Education - Schools'!$C$2:$C$30,A3) -> 0 | H3: 11 | I3: =IF(AND(H3<=10,F3<150),"High need, low coverage",IF(F3=0,"No ESSP yet","")) -> No ESSP yet
A4: Badulla | B4: =SUMIF('Food - All Deliveries'!$C$2:$C$108,A4,'Food - All Deliveries'!$D$2:$D$108) -> 4592 | C4: =COUNTIF('Food - All Deliveries'!$C$2:$C$108,A4) -> 18 | D4: 16.5 | E4: =IF(AND(D4>=20,B4<500),"High need, low coverage",IF(B4=0,"No food packs yet","")) | F4: =SUMIF('Education - Schools'!$C$2:$C$30,A4,'Education - Schools'!$D$2:$D$30) -> 192 | G4: =COUNTIF('Education - Schools'!$C$2:$C$30,A4) -> 2 | H4: 5 | I4: =IF(AND(H4<=10,F4<150),"High need, low coverage",IF(F4=0,"No ESSP yet",""))
A5: Batticaloa | B5: =SUMIF('Food - All Deliveries'!$C$2:$C$108,A5,'Food - All Deliveries'!$D$2:$D$108) -> 600 | C5: =COUNTIF('Food - All Deliveries'!$C$2:$C$108,A5) -> 4 | D5: 22.7 | E5: =IF(AND(D5>=20,B5<500),"High need, low coverage",IF(B5=0,"No food packs yet","")) | F5: =SUMIF('Education - Schools'!$C$2:$C$30,A5,'Education - Schools'!$D$2:$D$30) -> 270 | G5: =COUNTIF('Education - Schools'!$C$2:$C$30,A5) -> 1 | H5: 6 | I5: =IF(AND(H5<=10,F5<150),"High need, low coverage",IF(F5=0,"No ESSP yet",""))
A6: Colombo | B6: =SUMIF('Food - All Deliveries'!$C$2:$C$108,A6,'Food - All Deliveries'!$D$2:$D$108) -> 1047 | C6: =COUNTIF('Food - All Deliveries'!$C$2:$C$108,A6) -> 12 | D6: 6.7 | E6: =IF(AND(D6>=20,B6<500),"High need, low coverage",IF(B6=0,"No food packs yet","")) | F6: =SUMIF('Education - Schools'!$C$2:$C$30,A6,'Education - Schools'!$D$2:$D$30) -> 3 | G6: =COUNTIF('Education - Schools'!$C$2:$C$30,A6) -> 1 | H6: 22 | I6: =IF(AND(H6<=10,F6<150),"High need, low coverage",IF(F6=0,"No ESSP yet",""))
A7: Galle | B7: =SUMIF('Food - All Deliveries'!$C$2:$C$108,A7,'Food - All Deliveries'!$D$2:$D$108) -> 0 | C7: =COUNTIF('Food - All Deliveries'!$C$2:$C$108,A7) -> 0 | D7: 16.1 | E7: =IF(AND(D7>=20,B7<500),"High need, low coverage",IF(B7=0,"No food packs yet","")) -> No food packs yet | F7: =SUMIF('Education - Schools'!$C$2:$C$30,A7,'Education - Schools'!$D$2:$D$30) -> 658 | G7: =COUNTIF('Education - Schools'!$C$2:$C$30,A7) -> 7 | H7: 25 | I7: =IF(AND(H7<=10,F7<150),"High need, low coverage",IF(F7=0,"No ESSP yet",""))
A8: Gampaha | B8: =SUMIF('Food - All Deliveries'!$C$2:$C$108,A8,'Food - All Deliveries'!$D$2:$D$108) -> 380 | C8: =COUNTIF('Food - All Deliveries'!$C$2:$C$108,A8) -> 3 | D8: 14.9 | E8: =IF(AND(D8>=20,B8<500),"High need, low coverage",IF(B8=0,"No food packs yet","")) | F8: =SUMIF('Education - Schools'!$C$2:$C$30,A8,'Education - Schools'!$D$2:$D$30) -> 0 | G8: =COUNTIF('Education - Schools'!$C$2:$C$30,A8) -> 0 | H8: 18 | I8: =IF(AND(H8<=10,F8<150),"High need, low coverage",IF(F8=0,"No ESSP yet","")) -> No ESSP yet
A9: Hambantota | B9: =SUMIF('Food - All Deliveries'!$C$2:$C$108,A9,'Food - All Deliveries'!$D$2:$D$108) -> 0 | C9: =COUNTIF('Food - All Deliveries'!$C$2:$C$108,A9) -> 0 | D9: 11.9 | E9: =IF(AND(D9>=20,B9<500),"High need, low coverage",IF(B9=0,"No food packs yet","")) -> No food packs yet | F9: =SUMIF('Education - Schools'!$C$2:$C$30,A9,'Education - Schools'!$D$2:$D$30) -> 0 | G9: =COUNTIF('Education - Schools'!$C$2:$C$30,A9) -> 0 | H9: 15 | I9: =IF(AND(H9<=10,F9<150),"High need, low coverage",IF(F9=0,"No ESSP yet","")) -> No ESSP yet
A10: Jaffna | B10: =SUMIF('Food - All Deliveries'!$C$2:$C$108,A10,'Food - All Deliveries'!$D$2:$D$108) -> 760 | C10: =COUNTIF('Food - All Deliveries'!$C$2:$C$108,A10) -> 3 | D10: 15.4 | E10: =IF(AND(D10>=20,B10<500),"High need, low coverage",IF(B10=0,"No food packs yet","")) | F10: =SUMIF('Education - Schools'!$C$2:$C$30,A10,'Education - Schools'!$D$2:$D$30) -> 252 | G10: =COUNTIF('Education - Schools'!$C$2:$C$30,A10) -> 1 | H10: 17 | I10: =IF(AND(H10<=10,F10<150),"High need, low coverage",IF(F10=0,"No ESSP yet",""))
A11: Kalutara | B11: =SUMIF('Food - All Deliveries'!$C$2:$C$108,A11,'Food - All Deliveries'!$D$2:$D$108) -> 0 | C11: =COUNTIF('Food - All Deliveries'!$C$2:$C$108,A11) -> 0 | D11: 12.4 | E11: =IF(AND(D11>=20,B11<500),"High need, low coverage",IF(B11=0,"No food packs yet","")) -> No food packs yet | F11: =SUMIF('Education - Schools'!$C$2:$C$30,A11,'Education - Schools'!$D$2:$D$30) -> 0 | G11: =COUNTIF('Education - Schools'!$C$2:$C$30,A11) -> 0 | H11: 19 | I11: =IF(AND(H11<=10,F11<150),"High need, low coverage",IF(F11=0,"No ESSP yet","")) -> No ESSP yet
A12: Kandy | B12: =SUMIF('Food - All Deliveries'!$C$2:$C$108,A12,'Food - All Deliveries'!$D$2:$D$108) -> 1880 | C12: =COUNTIF('Food - All Deliveries'!$C$2:$C$108,A12) -> 15 | D12: 8.7 | E12: =IF(AND(D12>=20,B12<500),"High need, low coverage",IF(B12=0,"No food packs yet","")) | F12: =SUMIF('Education - Schools'!$C$2:$C$30,A12,'Education - Schools'!$D$2:$D$30) -> 30 | G12: =COUNTIF('Education - Schools'!$C$2:$C$30,A12) -> 1 | H12: 9 | I12: =IF(AND(H12<=10,F12<150),"High need, low coverage",IF(F12=0,"No ESSP yet","")) -> High need, low coverage
A13: Kegalle | B13: =SUMIF('Food - All Deliveries'!$C$2:$C$108,A13,'Food - All Deliveries'!$D$2:$D$108) -> 0 | C13: =COUNTIF('Food - All Deliveries'!$C$2:$C$108,A13) -> 0 | D13: 8.6 | E13: =IF(AND(D13>=20,B13<500),"High need, low coverage",IF(B13=0,"No food packs yet","")) -> No food packs yet | F13: =SUMIF('Education - Schools'!$C$2:$C$30,A13,'Education - Schools'!$D$2:$D$30) -> 0 | G13: =COUNTIF('Education - Schools'!$C$2:$C$30,A13) -> 0 | H13: 23 | I13: =IF(AND(H13<=10,F13<150),"High need, low coverage",IF(F13=0,"No ESSP yet","")) -> No ESSP yet
... A26: Vavuniya | B26: =SUMIF('Food - All Deliveries'!$C$2:$C$108,A26,'Food - All Deliveries'!$D$2:$D$108) -> 500 | C26: =COUNTIF('Food - All Deliveries'!$C$2:$C$108,A26) -> 3 | D26: 27.2 | E26: =IF(AND(D26>=20,B26<500),"High need, low coverage",IF(B26=0,"No food packs yet","")) | F26: =SUMIF('Education - Schools'!$C$2:$C$30,A26,'Education - Schools'!$D$2:$D$30) -> 76 | G26: =COUNTIF('Education - Schools'!$C$2:$C$30,A26) -> 2 | H26: 7 | I26: =IF(AND(H26<=10,F26<150),"High need, low coverage",IF(F26=0,"No ESSP yet","")) -> High need, low coverage
A27: Also: "Nuwara Eliya / Badulla" (shared delivery) and "Island-wide" ESSP requests are not in any single district row.
A28: Gap flag: food = WFP food insecurity ≥ 20% but < 500 packs; education = top-10 education priority but < 150 ESSP students.
A29: Need data: WFP food insecurity map 2024; education priority from the Education Needs workbook (MPI 2019 + O/L 2024).
